Workbook

Sheet Resumen
B1: =IF(ISNUMBER(Supuestos!B17),"Con "&Supuestos!B6&" eventos al año, la malla se paga sola en "&ROUND(Supuestos!B17,1)&" años","Con "&Supuestos!B6&" eventos al año la malla no se recupera: hacen falta más de "&ROUND(Rentabilidad!B20,1)&" usos por año")
B2: ="Idea final: malla sobre cables que reemplaza la carpa de $ 100.000 por evento. Se paga todo el día 1 y se evalúa a "&Supuestos!B15&" años."
B4: INVERSIÓN, PAGO ÚNICO DÍA 1 | E4: SE RECUPERA EN | H4: ="AHORRO NETO A "&Supuestos!B15&" AÑOS" | K4: TIR ANUAL
B5: =Supuestos!B13 | E5: =Supuestos!B17 | H5: =Supuestos!B19 | K5: =Supuestos!B21
B6: con IVA, todos los materiales | E6: ="equivale a "&Supuestos!B18&" usos de carpa" | H6: ="con "&Supuestos!B16&" reposiciones de lona" | K6: rendimiento de la inversión
B24: Render de la idea final a las 12:30: la malla cubre la zona del público.
B26: Lo que hay que saber a largo plazo
B27: CARPA QUE SE DEJA DE PAGAR | F27: REPOSICIÓN DE LA LONA | J27: USOS MÍNIMOS PARA SER RENTABLE
B28: =Supuestos!B12 | F28: =Supuestos!B14 | J28: =Rentabilidad!B20
B29: ="con "&Supuestos!B6&" eventos × $ 100.000" | F29: ="lona + cuerda, cada "&Supuestos!B8&" años" | J29: con menos, la malla nunca se recupera
B30: =IF(ISNUMBER(Supuestos!B22),"Cada reposición de la lona hace caer el ahorro acumulado: queda rentable sin recaídas desde el año "&ROUND(Supuestos!B22,1)&".","")
B31: ="A confirmar: "&Supuestos!B6&" eventos por año y dólar a $ "&Supuestos!B5&". Precios constantes. Reposición sin mano de obra ni plataforma."

Sheet Pago único
A1: Pago único el día 1
A2: Todo se paga junto al hacer los pedidos. Montos con IVA.
B4: Proveedor | C4: En dólares | D4: En pesos | E4: Total en pesos | F4: % del total
B5: Romela Toldos (lona) | C5: 17873 | D5: 0 | E5: =C5*Supuestos!$B$5+D5 | F5: =E5/$E$10
B6: Appelsa (postes y estructura) | C6: 4180.6228 | D6: 0 | E6: =C6*Supuestos!$B$5+D6 | F6: =E6/$E$10
B7: Bianchi (cables y accesorios) | C7: 503.78 | D7: 127301 | E7: =C7*Supuestos!$B$5+D7 | F7: =E7/$E$10
B8: Sodimac (anclajes) | C8: 0 | D8: 10146 | E8: =C8*Supuestos!$B$5+D8 | F8: =E8/$E$10
B9: Polietileno Obelisco (cuerda) | C9: 0 | D9: 14400 | E9: =C9*Supuestos!$B$5+D9 | F9: =E9/$E$10
B10: Total a pagar el día 1 | C10: =SUM(C5:C9) | D10: =SUM(D5:D9) | E10: =SUM(E5:E9) | F10: =SUM(F5:F9)
B11: Fuente: Gastos.xlsx (hoja Gastos), totales con IVA, precios al 1/10/2026. Si cambian allá, actualizar las celdas azules.

Sheet Rentabilidad
A1: Rentabilidad según los usos por año
A2: Todo incluye el desgaste de la lona: se repone entera cada L años. u = eventos por año.
A4: La ecuación
A5: Ahorro neto acumulado (exacto, con escalones): | B5: N(t) = u·c·t − I − R·(⌈t/L⌉ − 1)
A6: Primer cruce: años hasta que N(t) llega a 0: | B6: k = ⌈(I − u·c·L) / (u·c·L − R)⌉ (mínimo 0), t₁ = (I + k·R) / (u·c)
A7: Queda rentable sin recaídas desde: | B7: k′ = ⌈I / (u·c·L − R)⌉, t₂ = (I + (k′−1)·R) / (u·c)
A8: Aproximación de largo plazo (lona repartida): | B8: t*(u) = I / (u·c − R/L), válida solo si u·c > R/L
A9: Usos mínimos por año para que algún día sea rentable: | B9: u > R / (L·c)
A10: Cada vez que se repone la lona, el ahorro acumulado vuelve a caer: por eso hay "primer cruce" y "sin recaídas".
A12: Símbolo | B12: Valor | C12: Qué es
A13: u | B13: variable | C13: Usos (eventos) por año: la variable
A14: c | B14: =Supuestos!B7 | C14: Costo de la carpa por uso
A15: I | B15: =Supuestos!B13 | C15: Inversión inicial, pagada el día 1
A16: R | B16: =Supuestos!B14 | C16: Costo de reponer la lona (lona + cuerda)
A17: L | B17: =Supuestos!B8 | C17: Vida útil de la lona (años)
A19: Resultado clave
A20: Usos mínimos por año R / (L·c) | B20: =B16/(B17*B14) | C20: ="Con 1 uso al año se pierden $ "&TEXT(B16/B17-B14,"#,##0")&" por año por el desgaste de la lona: nunca se recupera. Con 2 o más, sí."
A23: Usos por año (u) | B23: Ahorro anual en carpa (u·c) | C23: Costo anual del desgaste de la lona (R/L) | D23: Neto por año | E23: Años para recuperar (primer cruce) t₁ | F23: Queda rentable sin recaídas desde t₂ | G23: Ahorro neto a 20 años (exacto) | H23: Aproximación t*(u)
A24: 1 | B24: =A24*$B$14 | C24: =$B$16/$B$17 | D24: =B24-C24 | E24: =IF($B24*Supuestos!$B$8>=Supuestos!$B$13,Supuestos!$B$13/$B24,IF($B24*Supuestos!$B$8<=Supuestos!$B$14,"nunca",(Supuestos!$B$13+ROUNDUP((Supuestos!$B$13-$B24*Supuestos!$B$8)/($B24*Supuestos!$B$8-Supuestos!$B$14),0)*Supuestos!$B$14)/$B24)) | F24: =IF($B24*Supuestos!$B$8<=Supuestos!$B$14,"nunca",IF(ROUNDUP(Supuestos!$B$13/($B24*Supuestos!$B$8-Supuestos!$B$14),0)<=1,IF($B24*Supuestos!$B$8>=Supuestos!$B$13,Supuestos!$B$13/$B24,IF($B24*Supuestos!$B$8<=Supuestos!$B$14,"nunca",(Supuestos!$B$13+ROUNDUP((Supuestos!$B$13-$B24*Supuestos!$B$8)/($B24*Supuestos!$B$8-Supuestos!$B$14),0)*Supuestos!$B$14)/$B24)),(Supuestos!$B$13+(ROUNDUP(Supuestos!$B$13/($B24*Supuestos!$B$8-Supuestos!$B$14),0)-1)*Supuestos!$B$14)/$B24)) | G24: =B24*Supuestos!$B$15-$B$15-$B$16*Supuestos!$B$16 | H24: =IF(D24>0,$B$15/D24,"nunca")
A25: 2 | B25: =A25*$B$14 | C25: =$B$16/$B$17 | D25: =B25-C25 | E25: =IF($B25*Supuestos!$B$8>=Supuestos!$B$13,Supuestos!$B$13/$B25,IF($B25*Supuestos!$B$8<=Supuestos!$B$14,"nunca",(Supuestos!$B$13+ROUNDUP((Supuestos!$B$13-$B25*Supuestos!$B$8)/($B25*Supuestos!$B$8-Supuestos!$B$14),0)*Supuestos!$B$14)/$B25)) | F25: =IF($B25*Supuestos!$B$8<=Supuestos!$B$14,"nunca",IF(ROUNDUP(Supuestos!$B$13/($B25*Supuestos!$B$8-Supuestos!$B$14),0)<=1,IF($B25*Supuestos!$B$8>=Supuestos!$B$13,Supuestos!$B$13/$B25,IF($B25*Supuestos!$B$8<=Supuestos!$B$14,"nunca",(Supuestos!$B$13+ROUNDUP((Supuestos!$B$13-$B25*Supuestos!$B$8)/($B25*Supuestos!$B$8-Supuestos!$B$14),0)*Supuestos!$B$14)/$B25)),(Supuestos!$B$13+(ROUNDUP(Supuestos!$B$13/($B25*Supuestos!$B$8-Supuestos!$B$14),0)-1)*Supuestos!$B$14)/$B25)) | G25: =B25*Supuestos!$B$15-$B$15-$B$16*Supuestos!$B$16 | H25: =IF(D25>0,$B$15/D25,"nunca")
A26: 3 | B26: =A26*$B$14 | C26: =$B$16/$B$17 | D26: =B26-C26 | E26: =IF($B26*Supuestos!$B$8>=Supuestos!$B$13,Supuestos!$B$13/$B26,IF($B26*Supuestos!$B$8<=Supuestos!$B$14,"nunca",(Supuestos!$B$13+ROUNDUP((Supuestos!$B$13-$B26*Supuestos!$B$8)/($B26*Supuestos!$B$8-Supuestos!$B$14),0)*Supuestos!$B$14)/$B26)) | F26: =IF($B26*Supuestos!$B$8<=Supuestos!$B$14,"nunca",IF(ROUNDUP(Supuestos!$B$13/($B26*Supuestos!$B$8-Supuestos!$B$14),0)<=1,IF($B26*Supuestos!$B$8>=Supuestos!$B$13,Supuestos!$B$13/$B26,IF($B26*Supuestos!$B$8<=Supuestos!$B$14,"nunca",(Supuestos!$B$13+ROUNDUP((Supuestos!$B$13-$B26*Supuestos!$B$8)/($B26*Supuestos!$B$8-Supuestos!$B$14),0)*Supuestos!$B$14)/$B26)),(Supuestos!$B$13+(ROUNDUP(Supuestos!$B$13/($B26*Supuestos!$B$8-Supuestos!$B$14),0)-1)*Supuestos!$B$14)/$B26)) | G26: =B26*Supuestos!$B$15-$B$15-$B$16*Supuestos!$B$16 | H26: =IF(D26>0,$B$15/D26,"nunca")
A27: 4 | B27: =A27*$B$14 | C27: =$B$16/$B$17 | D27: =B27-C27 | E27: =IF($B27*Supuestos!$B$8>=Supuestos!$B$13,Supuestos!$B$13/$B27,IF($B27*Supuestos!$B$8<=Supuestos!$B$14,"nunca",(Supuestos!$B$13+ROUNDUP((Supuestos!$B$13-$B27*Supuestos!$B$8)/($B27*Supuestos!$B$8-Supuestos!$B$14),0)*Supuestos!$B$14)/$B27)) | F27: =IF($B27*Supuestos!$B$8<=Supuestos!$B$14,"nunca",IF(ROUNDUP(Supuestos!$B$13/($B27*Supuestos!$B$8-Supuestos!$B$14),0)<=1,IF($B27*Supuestos!$B$8>=Supuestos!$B$13,Supuestos!$B$13/$B27,IF($B27*Supuestos!$B$8<=Supuestos!$B$14,"nunca",(Supuestos!$B$13+ROUNDUP((Supuestos!$B$13-$B27*Supuestos!$B$8)/($B27*Supuestos!$B$8-Supuestos!$B$14),0)*Supuestos!$B$14)/$B27)),(Supuestos!$B$13+(ROUNDUP(Supuestos!$B$13/($B27*Supuestos!$B$8-Supuestos!$B$14),0)-1)*Supuestos!$B$14)/$B27)) | G27: =B27*Supuestos!$B$15-$B$15-$B$16*Supuestos!$B$16 | H27: =IF(D27>0,$B$15/D27,"nunca")
A28: 5 | B28: =A28*$B$14 | C28: =$B$16/$B$17 | D28: =B28-C28 | E28: =IF($B28*Supuestos!$B$8>=Supuestos!$B$13,Supuestos!$B$13/$B28,IF($B28*Supuestos!$B$8<=Supuestos!$B$14,"nunca",(Supuestos!$B$13+ROUNDUP((Supuestos!$B$13-$B28*Supuestos!$B$8)/($B28*Supuestos!$B$8-Supuestos!$B$14),0)*Supuestos!$B$14)/$B28)) | F28: =IF($B28*Supuestos!$B$8<=Supuestos!$B$14,"nunca",IF(ROUNDUP(Supuestos!$B$13/($B28*Supuestos!$B$8-Supuestos!$B$14),0)<=1,IF($B28*Supuestos!$B$8>=Supuestos!$B$13,Supuestos!$B$13/$B28,IF($B28*Supuestos!$B$8<=Supuestos!$B$14,"nunca",(Supuestos!$B$13+ROUNDUP((Supuestos!$B$13-$B28*Supuestos!$B$8)/($B28*Supuestos!$B$8-Supuestos!$B$14),0)*Supuestos!$B$14)/$B28)),(Supuestos!$B$13+(ROUNDUP(Supuestos!$B$13/($B28*Supuestos!$B$8-Supuestos!$B$14),0)-1)*Supuestos!$B$14)/$B28)) | G28: =B28*Supuestos!$B$15-$B$15-$B$16*Supuestos!$B$16 | H28: =IF(D28>0,$B$15/D28,"nunca")
A29: 6 | B29: =A29*$B$14 | C29: =$B$16/$B$17 | D29: =B29-C29 | E29: =IF($B29*Supuestos!$B$8>=Supuestos!$B$13,Supuestos!$B$13/$B29,IF($B29*Supuestos!$B$8<=Supuestos!$B$14,"nunca",(Supuestos!$B$13+ROUNDUP((Supuestos!$B$13-$B29*Supuestos!$B$8)/($B29*Supuestos!$B$8-Supuestos!$B$14),0)*Supuestos!$B$14)/$B29)) | F29: =IF($B29*Supuestos!$B$8<=Supuestos!$B$14,"nunca",IF(ROUNDUP(Supuestos!$B$13/($B29*Supuestos!$B$8-Supuestos!$B$14),0)<=1,IF($B29*Supuestos!$B$8>=Supuestos!$B$13,Supuestos!$B$13/$B29,IF($B29*Supuestos!$B$8<=Supuestos!$B$14,"nunca",(Supuestos!$B$13+ROUNDUP((Supuestos!$B$13-$B29*Supuestos!$B$8)/($B29*Supuestos!$B$8-Supuestos!$B$14),0)*Supuestos!$B$14)/$B29)),(Supuestos!$B$13+(ROUNDUP(Supuestos!$B$13/($B29*Supuestos!$B$8-Supuestos!$B$14),0)-1)*Supuestos!$B$14)/$B29)) | G29: =B29*Supuestos!$B$15-$B$15-$B$16*Supuestos!$B$16 | H29: =IF(D29>0,$B$15/D29,"nunca")
A30: 7 | B30: =A30*$B$14 | C30: =$B$16/$B$17 | D30: =B30-C30 | E30: =IF($B30*Supuestos!$B$8>=Supuestos!$B$13,Supuestos!$B$13/$B30,IF($B30*Supuestos!$B$8<=Supuestos!$B$14,"nunca",(Supuestos!$B$13+ROUNDUP((Supuestos!$B$13-$B30*Supuestos!$B$8)/($B30*Supuestos!$B$8-Supuestos!$B$14),0)*Supuestos!$B$14)/$B30)) | F30: =IF($B30*Supuestos!$B$8<=Supuestos!$B$14,"nunca",IF(ROUNDUP(Supuestos!$B$13/($B30*Supuestos!$B$8-Supuestos!$B$14),0)<=1,IF($B30*Supuestos!$B$8>=Supuestos!$B$13,Supuestos!$B$13/$B30,IF($B30*Supuestos!$B$8<=Supuestos!$B$14,"nunca",(Supuestos!$B$13+ROUNDUP((Supuestos!$B$13-$B30*Supuestos!$B$8)/($B30*Supuestos!$B$8-Supuestos!$B$14),0)*Supuestos!$B$14)/$B30)),(Supuestos!$B$13+(ROUNDUP(Supuestos!$B$13/($B30*Supuestos!$B$8-Supuestos!$B$14),0)-1)*Supuestos!$B$14)/$B30)) | G30: =B30*Supuestos!$B$15-$B$15-$B$16*Supuestos!$B$16 | H30: =IF(D30>0,$B$15/D30,"nunca")
A31: 8 | B31: =A31*$B$14 | C31: =$B$16/$B$17 | D31: =B31-C31 | E31: =IF($B31*Supuestos!$B$8>=Supuestos!$B$13,Supuestos!$B$13/$B31,IF($B31*Supuestos!$B$8<=Supuestos!$B$14,"nunca",(Supuestos!$B$13+ROUNDUP((Supuestos!$B$13-$B31*Supuestos!$B$8)/($B31*Supuestos!$B$8-Supuestos!$B$14),0)*Supuestos!$B$14)/$B31)) | F31: =IF($B31*Supuestos!$B$8<=Supuestos!$B$14,"nunca",IF(ROUNDUP(Supuestos!$B$13/($B31*Supuestos!$B$8-Supuestos!$B$14),0)<=1,IF($B31*Supuestos!$B$8>=Supuestos!$B$13,Supuestos!$B$13/$B31,IF($B31*Supuestos!$B$8<=Supuestos!$B$14,"nunca",(Supuestos!$B$13+ROUNDUP((Supuestos!$B$13-$B31*Supuestos!$B$8)/($B31*Supuestos!$B$8-Supuestos!$B$14),0)*Supuestos!$B$14)/$B31)),(Supuestos!$B$13+(ROUNDUP(Supuestos!$B$13/($B31*Supuestos!$B$8-Supuestos!$B$14),0)-1)*Supuestos!$B$14)/$B31)) | G31: =B31*Supuestos!$B$15-$B$15-$B$16*Supuestos!$B$16 | H31: =IF(D31>0,$B$15/D31,"nunca")
A32: 9 | B32: =A32*$B$14 | C32: =$B$16/$B$17 | D32: =B32-C32 | E32: =IF($B32*Supuestos!$B$8>=Supuestos!$B$13,Supuestos!$B$13/$B32,IF($B32*Supuestos!$B$8<=Supuestos!$B$14,"nunca",(Supuestos!$B$13+ROUNDUP((Supuestos!$B$13-$B32*Supuestos!$B$8)/($B32*Supuestos!$B$8-Supuestos!$B$14),0)*Supuestos!$B$14)/$B32)) | F32: =IF($B32*Supuestos!$B$8<=Supuestos!$B$14,"nunca",IF(ROUNDUP(Supuestos!$B$13/($B32*Supuestos!$B$8-Supuestos!$B$14),0)<=1,IF($B32*Supuestos!$B$8>=Supuestos!$B$13,Supuestos!$B$13/$B32,IF($B32*Supuestos!$B$8<=Supuestos!$B$14,"nunca",(Supuestos!$B$13+ROUNDUP((Supuestos!$B$13-$B32*Supuestos!$B$8)/($B32*Supuestos!$B$8-Supuestos!$B$14),0)*Supuestos!$B$14)/$B32)),(Supuestos!$B$13+(ROUNDUP(Supuestos!$B$13/($B32*Supuestos!$B$8-Supuestos!$B$14),0)-1)*Supuestos!$B$14)/$B32)) | G32: =B32*Supuestos!$B$15-$B$15-$B$16*Supuestos!$B$16 | H32: =IF(D32>0,$B$15/D32,"nunca")
A33: 10 | B33: =A33*$B$14 | C33: =$B$16/$B$17 | D33: =B33-C33 | E33: =IF($B33*Supuestos!$B$8>=Supuestos!$B$13,Supuestos!$B$13/$B33,IF($B33*Supuestos!$B$8<=Supuestos!$B$14,"nunca",(Supuestos!$B$13+ROUNDUP((Supuestos!$B$13-$B33*Supuestos!$B$8)/($B33*Supuestos!$B$8-Supuestos!$B$14),0)*Supuestos!$B$14)/$B33)) | F33: =IF($B33*Supuestos!$B$8<=Supuestos!$B$14,"nunca",IF(ROUNDUP(Supuestos!$B$13/($B33*Supuestos!$B$8-Supuestos!$B$14),0)<=1,IF($B33*Supuestos!$B$8>=Supuestos!$B$13,Supuestos!$B$13/$B33,IF($B33*Supuestos!$B$8<=Supuestos!$B$14,"nunca",(Supuestos!$B$13+ROUNDUP((Supuestos!$B$13-$B33*Supuestos!$B$8)/($B33*Supuestos!$B$8-Supuestos!$B$14),0)*Supuestos!$B$14)/$B33)),(Supuestos!$B$13+(ROUNDUP(Supuestos!$B$13/($B33*Supuestos!$B$8-Supuestos!$B$14),0)-1)*Supuestos!$B$14)/$B33)) | G33: =B33*Supuestos!$B$15-$B$15-$B$16*Supuestos!$B$16 | H33: =IF(D33>0,$B$15/D33,"nunca")
A34: 11 | B34: =A34*$B$14 | C34: =$B$16/$B$17 | D34: =B34-C34 | E34: =IF($B34*Supuestos!$B$8>=Supuestos!$B$13,Supuestos!$B$13/$B34,IF($B34*Supuestos!$B$8<=Supuestos!$B$14,"nunca",(Supuestos!$B$13+ROUNDUP((Supuestos!$B$13-$B34*Supuestos!$B$8)/($B34*Supuestos!$B$8-Supuestos!$B$14),0)*Supuestos!$B$14)/$B34)) | F34: =IF($B34*Supuestos!$B$8<=Supuestos!$B$14,"nunca",IF(ROUNDUP(Supuestos!$B$13/($B34*Supuestos!$B$8-Supuestos!$B$14),0)<=1,IF($B34*Supuestos!$B$8>=Supuestos!$B$13,Supuestos!$B$13/$B34,IF($B34*Supuestos!$B$8<=Supuestos!$B$14,"nunca",(Supuestos!$B$13+ROUNDUP((Supuestos!$B$13-$B34*Supuestos!$B$8)/($B34*Supuestos!$B$8-Supuestos!$B$14),0)*Supuestos!$B$14)/$B34)),(Supuestos!$B$13+(ROUNDUP(Supuestos!$B$13/($B34*Supuestos!$B$8-Supuestos!$B$14),0)-1)*Supuestos!$B$14)/$B34)) | G34: =B34*Supuestos!$B$15-$B$15-$B$16*Supuestos!$B$16 | H34: =IF(D34>0,$B$15/D34,"nunca")
A35: 12 | B35: =A35*$B$14 | C35: =$B$16/$B$17 | D35: =B35-C35 | E35: =IF($B35*Supuestos!$B$8>=Supuestos!$B$13,Supuestos!$B$13/$B35,IF($B35*Supuestos!$B$8<=Supuestos!$B$14,"nunca",(Supuestos!$B$13+ROUNDUP((Supuestos!$B$13-$B35*Supuestos!$B$8)/($B35*Supuestos!$B$8-Supuestos!$B$14),0)*Supuestos!$B$14)/$B35)) | F35: =IF($B35*Supuestos!$B$8<=Supuestos!$B$14,"nunca",IF(ROUNDUP(Supuestos!$B$13/($B35*Supuestos!$B$8-Supuestos!$B$14),0)<=1,IF($B35*Supuestos!$B$8>=Supuestos!$B$13,Supuestos!$B$13/$B35,IF($B35*Supuestos!$B$8<=Supuestos!$B$14,"nunca",(Supuestos!$B$13+ROUNDUP((Supuestos!$B$13-$B35*Supuestos!$B$8)/($B35*Supuestos!$B$8-Supuestos!$B$14),0)*Supuestos!$B$14)/$B35)),(Supuestos!$B$13+(ROUNDUP(Supuestos!$B$13/($B35*Supuestos!$B$8-Supuestos!$B$14),0)-1)*Supuestos!$B$14)/$B35)) | G35: =B35*Supuestos!$B$15-$B$15-$B$16*Supuestos!$B$16 | H35: =IF(D35>0,$B$15/D35,"nunca")
A37: • t₁ y t₂ salen del modelo exacto. La aproximación t*(u) reparte el costo de la lona en el tiempo.

Sheet Supuestos
A1: Supuestos y cálculos a largo plazo
A2: Los valores en azul se pueden cambiar; todo el libro se recalcula. Amarillo = supuesto propio a confirmar.
A4: Supuesto | B4: Valor | C4: Unidad | D4: De dónde sale
A5: Tipo de cambio | B5: 40 | C5: $ por US$ | D5: SUPUESTO: confirmar el dólar del día de pago. Solo pasa todo a pesos.
A6: Eventos multitudinarios por año en el patio | B6: 6 | C6: eventos | D6: SUPUESTO: reemplazar por el número real del colegio.
A7: Costo de la carpa por uso | B7: 100000 | C7: $ por evento | D7: Dato del equipo: hoy se paga una carpa de $ 100.000 cada vez.
A8: Vida útil de la lona de la malla | B8: 5 | C8: años | D8: Dato confirmado por el proveedor (falta confirmar si cubre ojales y costuras). El desgaste es por tiempo al sol, no por usos. La estructura se supone que dura todo el horizonte.
A10: Cálculos clave
A11: Indicador | B11: Valor | C11: Cómo se calcula
A12: Gasto anual en carpa | B12: =B6*B7 | C12: Eventos por año × costo de la carpa
A13: Inversión inicial (pago único, día 1) | B13: ='Pago único'!E10 | C13: Total con IVA de la hoja Pago único
A14: Costo de reponer la lona (lona + cuerda) | B14: ='Pago único'!E5+'Pago único'!E9 | C14: Lona de Romela + cuerda para atarla, a precios de hoy. Sin mano de obra ni plataforma (sin precio).
A15: Horizonte de evaluación (años) | B15: =MAX(A31:A51) | C15: Largo de la tabla de flujos de abajo
A16: Reposiciones de la lona en el horizonte | B16: =MAX(0,ROUNDUP(B15/B8,0)-1) | C16: La lona se repone al terminar su vida útil
A17: Años para recuperar la inversión (primer cruce) | B17: =IF(B12*$B$8>=$B$13,$B$13/B12,IF(B12*$B$8<=$B$14,"nunca",($B$13+ROUNDUP(($B$13-B12*$B$8)/(B12*$B$8-$B$14),0)*$B$14)/B12)) | C17: Con desgaste: descuenta cada reposición de la lona (hoja Rentabilidad)
A18: Eventos para igualar la inversión | B18: =IF(ISNUMBER(B17),ROUNDUP(B17*B6,0),"nunca") | C18: Usos de carpa evitados hasta recuperar la inversión (incluye reposiciones)
A19: Ahorro neto en el horizonte | B19: =B12*B15-B13-B14*B16 | C19: Carpa evitada − inversión − reposiciones de lona
A20: Retorno anual neto del desgaste de la lona | B20: =(B12-B14/B8)/B13 | C20: (Ahorro anual − costo anual de la lona) ÷ inversión inicial
A21: TIR anual (rendimiento de la inversión) | B21: =IFERROR(IRR(E31:E51),"no se recupera") | C21: Sobre los flujos de la tabla, con reposiciones
A22: Queda rentable sin recaídas desde (años) | B22: =IF(B12*$B$8<=$B$14,"nunca",IF(ROUNDUP($B$13/(B12*$B$8-$B$14),0)<=1,IF(B12*$B$8>=$B$13,$B$13/B12,IF(B12*$B$8<=$B$14,"nunca",($B$13+ROUNDUP(($B$13-B12*$B$8)/(B12*$B$8-$B$14),0)*$B$14)/B12)),($B$13+(ROUNDUP($B$13/(B12*$B$8-$B$14),0)-1)*$B$14)/B12)) | C22: Después de cada reposición el ahorro acumulado cae; esta es la fecha desde la que ya no vuelve a ser negativo
A23: ¿Y si los eventos por año son otros?
A24: Eventos por año | B24: Gasto anual en carpa | C24: Años para recuperar (primer cruce) | D24: Ahorro neto en el horizonte | E24: Sin recaídas desde (años)
A25: 1 | B25: =A25*$B$7 | C25: =IF(B25*$B$8>=$B$13,$B$13/B25,IF(B25*$B$8<=$B$14,"nunca",($B$13+ROUNDUP(($B$13-B25*$B$8)/(B25*$B$8-$B$14),0)*$B$14)/B25)) | D25: =B25*$B$15-$B$13-$B$14*$B$16 | E25: =IF(B25*$B$8<=$B$14,"nunca",IF(ROUNDUP($B$13/(B25*$B$8-$B$14),0)<=1,IF(B25*$B$8>=$B$13,$B$13/B25,IF(B25*$B$8<=$B$14,"nunca",($B$13+ROUNDUP(($B$13-B25*$B$8)/(B25*$B$8-$B$14),0)*$B$14)/B25)),($B$13+(ROUNDUP($B$13/(B25*$B$8-$B$14),0)-1)*$B$14)/B25))
A26: 2 | B26: =A26*$B$7 | C26: =IF(B26*$B$8>=$B$13,$B$13/B26,IF(B26*$B$8<=$B$14,"nunca",($B$13+ROUNDUP(($B$13-B26*$B$8)/(B26*$B$8-$B$14),0)*$B$14)/B26)) | D26: =B26*$B$15-$B$13-$B$14*$B$16 | E26: =IF(B26*$B$8<=$B$14,"nunca",IF(ROUNDUP($B$13/(B26*$B$8-$B$14),0)<=1,IF(B26*$B$8>=$B$13,$B$13/B26,IF(B26*$B$8<=$B$14,"nunca",($B$13+ROUNDUP(($B$13-B26*$B$8)/(B26*$B$8-$B$14),0)*$B$14)/B26)),($B$13+(ROUNDUP($B$13/(B26*$B$8-$B$14),0)-1)*$B$14)/B26))
A27: 6 | B27: =A27*$B$7 | C27: =IF(B27*$B$8>=$B$13,$B$13/B27,IF(B27*$B$8<=$B$14,"nunca",($B$13+ROUNDUP(($B$13-B27*$B$8)/(B27*$B$8-$B$14),0)*$B$14)/B27)) | D27: =B27*$B$15-$B$13-$B$14*$B$16 | E27: =IF(B27*$B$8<=$B$14,"nunca",IF(ROUNDUP($B$13/(B27*$B$8-$B$14),0)<=1,IF(B27*$B$8>=$B$13,$B$13/B27,IF(B27*$B$8<=$B$14,"nunca",($B$13+ROUNDUP(($B$13-B27*$B$8)/(B27*$B$8-$B$14),0)*$B$14)/B27)),($B$13+(ROUNDUP($B$13/(B27*$B$8-$B$14),0)-1)*$B$14)/B27))
A29: Flujo año por año
A30: Año | B30: Carpa acumulada | C30: Malla acumulada (con reposición) | D30: Ahorro neto acumulado | E30: Flujo neto del año
A31: 0 | B31: =A31*$B$12 | C31: =$B$13+$B$14*MAX(0,ROUNDUP(A31/$B$8,0)-1) | D31: =B31-C31 | E31: =-$B$13
A32: 1 | B32: =A32*$B$12 | C32: =$B$13+$B$14*MAX(0,ROUNDUP(A32/$B$8,0)-1) | D32: =B32-C32 | E32: =$B$12-IF(MOD(A32-1,$B$8)=0,$B$14,0)*IF(A32>1,1,0)
A33: 2 | B33: =A33*$B$12 | C33: =$B$13+$B$14*MAX(0,ROUNDUP(A33/$B$8,0)-1) | D33: =B33-C33 | E33: =$B$12-IF(MOD(A33-1,$B$8)=0,$B$14,0)*IF(A33>1,1,0)
A34: 3 | B34: =A34*$B$12 | C34: =$B$13+$B$14*MAX(0,ROUNDUP(A34/$B$8,0)-1) | D34: =B34-C34 | E34: =$B$12-IF(MOD(A34-1,$B$8)=0,$B$14,0)*IF(A34>1,1,0)
A35: 4 | B35: =A35*$B$12 | C35: =$B$13+$B$14*MAX(0,ROUNDUP(A35/$B$8,0)-1) | D35: =B35-C35 | E35: =$B$12-IF(MOD(A35-1,$B$8)=0,$B$14,0)*IF(A35>1,1,0)
A36: 5 | B36: =A36*$B$12 | C36: =$B$13+$B$14*MAX(0,ROUNDUP(A36/$B$8,0)-1) | D36: =B36-C36 | E36: =$B$12-IF(MOD(A36-1,$B$8)=0,$B$14,0)*IF(A36>1,1,0)
A37: 6 | B37: =A37*$B$12 | C37: =$B$13+$B$14*MAX(0,ROUNDUP(A37/$B$8,0)-1) | D37: =B37-C37 | E37: =$B$12-IF(MOD(A37-1,$B$8)=0,$B$14,0)*IF(A37>1,1,0)
A38: 7 | B38: =A38*$B$12 | C38: =$B$13+$B$14*MAX(0,ROUNDUP(A38/$B$8,0)-1) | D38: =B38-C38 | E38: =$B$12-IF(MOD(A38-1,$B$8)=0,$B$14,0)*IF(A38>1,1,0)
A39: 8 | B39: =A39*$B$12 | C39: =$B$13+$B$14*MAX(0,ROUNDUP(A39/$B$8,0)-1) | D39: =B39-C39 | E39: =$B$12-IF(MOD(A39-1,$B$8)=0,$B$14,0)*IF(A39>1,1,0)
A40: 9 | B40: =A40*$B$12 | C40: =$B$13+$B$14*MAX(0,ROUNDUP(A40/$B$8,0)-1) | D40: =B40-C40 | E40: =$B$12-IF(MOD(A40-1,$B$8)=0,$B$14,0)*IF(A40>1,1,0)
A41: 10 | B41: =A41*$B$12 | C41: =$B$13+$B$14*MAX(0,ROUNDUP(A41/$B$8,0)-1) | D41: =B41-C41 | E41: =$B$12-IF(MOD(A41-1,$B$8)=0,$B$14,0)*IF(A41>1,1,0)
A42: 11 | B42: =A42*$B$12 | C42: =$B$13+$B$14*MAX(0,ROUNDUP(A42/$B$8,0)-1) | D42: =B42-C42 | E42: =$B$12-IF(MOD(A42-1,$B$8)=0,$B$14,0)*IF(A42>1,1,0)
A43: 12 | B43: =A43*$B$12 | C43: =$B$13+$B$14*MAX(0,ROUNDUP(A43/$B$8,0)-1) | D43: =B43-C43 | E43: =$B$12-IF(MOD(A43-1,$B$8)=0,$B$14,0)*IF(A43>1,1,0)
...
