Workbook

Sheet Resumen
B1: =IF(ISNUMBER('Cálculo'!B17),"Con "&'Cálculo'!B6&" eventos al año, la malla se paga sola en "&ROUND('Cálculo'!B17,1)&" años","Con "&'Cálculo'!B6&" eventos al año la malla no se recupera: hacen falta más de "&ROUND('Cálculo'!B20,1)&" usos por año") -> Con 2 eventos al año, la malla se paga sola en 8,9 años
B2: ="Idea final: malla sobre cables que reemplaza la carpa de $ 100.000 por evento. Se paga todo el día 1 y se evalúa a "&'Cálculo'!B15&" años." -> Idea final: malla sobre cables que reemplaza la carpa de $ 100.000 por evento. Se paga todo el día 1 y se evalúa a 20 años.
B4: INVERSIÓN, PAGO ÚNICO DÍA 1 | E4: SE RECUPERA EN | H4: ="AHORRO NETO A "&'Cálculo'!B15&" AÑOS" -> AHORRO NETO A 20 AÑOS | K4: TIR ANUAL
B5: ='Cálculo'!B13 -> 1054143.1 | E5: ='Cálculo'!B17 -> 8.9173156 | H5: ='Cálculo'!B19 -> 757896.89 | K5: ='Cálculo'!B21 -> 0.06774256
B6: con IVA, todos los materiales | E6: ="lona "&'Cálculo'!B8&" años · equivale a "&'Cálculo'!B18&" usos de carpa" -> lona 5 años · equivale a 18 usos de carpa | H6: ="lona "&'Cálculo'!B8&" años · "&'Cálculo'!B16&" reposiciones de lona" -> lona 5 años · 3 reposiciones de lona | K6: ="lona "&'Cálculo'!B8&" años · rendimiento anual" -> lona 5 años · rendimiento anual
B7: igual en los dos casos | E7: ="Realista (lona "&'Cálculo'!B9&" años): "&IF(ISNUMBER('Cálculo'!C17),ROUND('Cálculo'!C17,1)&" años","nunca") -> Realista (lona 10 años): 5,3 años | H7: ="Realista: $ "&TEXT('Cálculo'!C19,"#,##0") -> Realista: $ 2.216.537 | K7: ="Realista: "&IF(ISNUMBER('Cálculo'!C21),ROUND('Cálculo'!C21*100,1)&"%","no se recupera") -> Realista: 15,8%
B24: Render de la idea final a las 12:30: la malla cubre la zona del público.
B26: Lo que hay que saber a largo plazo
B27: CARPA QUE SE DEJA DE PAGAR | F27: REPOSICIÓN DE LA LONA | J27: USOS MÍNIMOS PARA SER RENTABLE
B28: ='Cálculo'!B12 -> 200000 | F28: ='Cálculo'!B14 -> 729320 | J28: ='Cálculo'!B20 -> 1.45864
B29: ="con "&'Cálculo'!B6&" eventos × $ 100.000" -> con 2 eventos × $ 100.000 | F29: ="lona + cuerda, cada "&'Cálculo'!B8&" años" -> lona + cuerda, cada 5 años | J29: conservador: con menos, la malla nunca se recupera
B30: =IF(ISNUMBER('Cálculo'!B22),"Cada reposición de la lona hace caer el ahorro acumulado: queda rentable sin recaídas desde el año "&ROUND('Cálculo'!B22,1)&".","") -> Cada reposición de la lona hace caer el ahorro acumulado: queda rentable sin recaídas desde el año 16,2.
B31: ="A confirmar: "&'Cálculo'!B6&" eventos por año, dólar a $ "&'Cálculo'!B5&" y lona de "&'Cálculo'!B9&" años del caso realista (sin confirmar con el proveedor). Precios constantes, sin mano de obra." -> A confirmar: 2 eventos por año, dólar a $ 40 y lona de 10 años del caso realista (sin confirmar con el proveedor). Precios constantes, sin mano de obra.
B32: ="Caso conservador (lona "&'Cálculo'!B8&" años): "&IF(ISNUMBER('Cálculo'!B17),ROUND('Cálculo'!B17,1)&" años","nunca se recupera")&" · Caso realista (lona guardada, "&'Cálculo'!B9&" años; supuesto a confirmar): "&IF(ISNUMBER('Cálculo'!C17),ROUND('Cálculo'!C17,1)&" años","nunca se recupera") -> Caso conservador (lona 5 años): 8,9 años · Caso realista (lona guardada, 10 años; supuesto a confirmar): 5,3 años
B33: ="Caso realista: ahorro neto a "&'Cálculo'!B15&" años $ "&TEXT('Cálculo'!C19,"#,##0")&" · TIR "&IF(ISNUMBER('Cálculo'!C21),ROUND('Cálculo'!C21*100,1)&"%","no se recupera")&" · usos mínimos "&ROUND('Cálculo'!C20,1)&" por año (conservador: "&ROUND('Cálculo'!B20,1)&")." -> Caso realista: ahorro neto a 20 años $ 2.216.537 · TIR 15,8% · usos mínimos 0,7 por año (conservador: 1,5).

Sheet Cálculo
A1: Cálculo y supuestos
A2: Los valores en azul se pueden cambiar; todo el libro se recalcula. Amarillo = supuesto propio a confirmar.
A4: Supuesto | B4: Valor | C4: Unidad | D4: De dónde sale
A5: Tipo de cambio | B5: 40 | C5: $ por US$ | D5: Supuesto: confirmar el dólar el día de pago. Solo pasa todo a pesos.
A6: Eventos multitudinarios por año en el patio | B6: 2 | C6: eventos | D6: Supuesto: 2 eventos grandes por año. Reemplazar por el número real del colegio.
A7: Costo de la carpa por uso | B7: 100000 | C7: $ por evento | D7: Dato del equipo: hoy se paga una carpa de $ 100.000 cada vez.
A8: Vida útil de la lona de la malla | B8: 5 | C8: años | D8: Dato del proveedor (falta confirmar si cubre ojales y costuras). El desgaste es por tiempo al sol, no por usos.
A9: Vida útil realista de la lona (guardada casi todo el año) | B9: 10 | C9: años | D9: SIN CONFIRMAR con Romela Toldos (099 664 452): supuesto del equipo. Guardada casi todo el año, la lona dura más.
A10: Cálculos clave
A11: Indicador | B11: ="Valor: caso conservador (lona "&B8&" años)" -> Valor: caso conservador (lona 5 años) | C11: ="Valor: caso realista (lona "&B9&" años)" -> Valor: caso realista (lona 10 años) | D11: Cómo se calcula
A12: Gasto anual en carpa | B12: =B6*B7 -> 200000 | C12: =B12 -> 200000 | D12: Eventos por año × costo de la carpa
A13: Inversión inicial (pago único, día 1) | B13: =D30 -> 1054143.1 | C13: =B13 -> 1054143.1 | D13: Total con IVA del bloque «Pago único» de abajo
A14: Costo de reponer la lona (lona + cuerda) | B14: =D25+D29 -> 729320 | C14: =B14 -> 729320 | D14: Lona de Romela + cuerda, a precios de hoy. Sin mano de obra ni plataforma.
A15: Horizonte de evaluación (años) | B15: =MAX(A45:A65) -> 20 | C15: =B15 -> 20 | D15: Largo de la tabla de flujos de abajo
A16: Reposiciones de la lona en el horizonte | B16: =MAX(0,ROUNDUP(B15/B8,0)-1) -> 3 | C16: =MAX(0,ROUNDUP(B15/B9,0)-1) -> 1 | D16: La lona se repone al terminar su vida útil
A17: Años para recuperar la inversión (primer cruce) | B17: =IF(B12*$B$8>=$B$13,$B$13/B12,IF(B12*$B$8<=$B$14,"nunca",($B$13+ROUNDUP(($B$13-B12*$B$8)/(B12*$B$8-$B$14),0)*$B$14)/B12)) -> 8.9173156 | C17: =IF(B12*$B$9>=$B$13,$B$13/B12,IF(B12*$B$9<=$B$14,"nunca",($B$13+ROUNDUP(($B$13-B12*$B$9)/(B12*$B$9-$B$14),0)*$B$14)/B12)) -> 5.2707156 | D17: Descuenta cada reposición de la lona
A18: Eventos para igualar la inversión | B18: =IF(ISNUMBER(B17),ROUNDUP(B17*B6,0),"nunca") -> 18 | C18: =IF(ISNUMBER(C17),ROUNDUP(C17*B6,0),"nunca") -> 11 | D18: Usos de carpa evitados hasta recuperar la inversión
A19: Ahorro neto en el horizonte | B19: =B12*B15-B13-B14*B16 -> 757896.89 | C19: =B12*B15-B13-B14*C16 -> 2216536.9 | D19: Carpa evitada − inversión − reposiciones de lona
A20: Usos mínimos por año para ser rentable | B20: =B14/(B8*B7) -> 1.45864 | C20: =B14/(B9*B7) -> 0.72932 | D20: Con menos usos, el desgaste de la lona se come todo el ahorro
A21: TIR anual (rendimiento de la inversión) | B21: =IFERROR(IRR(E45:E65),"no se recupera") -> 0.06774256 | C21: =IFERROR(IRR(F45:F65),"no se recupera") -> 0.1578213 | D21: Sobre los flujos de la tabla, con reposiciones
A22: Queda rentable sin recaídas desde (años) | B22: =IF(B12*$B$8<=$B$14,"nunca",IF(ROUNDUP($B$13/(B12*$B$8-$B$14),0)<=1,IF(B12*$B$8>=$B$13,$B$13/B12,IF(B12*$B$8<=$B$14,"nunca",($B$13+ROUNDUP(($B$13-B12*$B$8)/(B12*$B$8-$B$14),0)*$B$14)/B12)),($B$13+(ROUNDUP($B$13/(B12*$B$8-$B$14),0)-1)*$B$14)/B12)) -> 16.210516 | C22: =IF(B12*$B$9<=$B$14,"nunca",IF(ROUNDUP($B$13/(B12*$B$9-$B$14),0)<=1,IF(B12*$B$9>=$B$13,$B$13/B12,IF(B12*$B$9<=$B$14,"nunca",($B$13+ROUNDUP(($B$13-B12*$B$9)/(B12*$B$9-$B$14),0)*$B$14)/B12)),($B$13+(ROUNDUP($B$13/(B12*$B$9-$B$14),0)-1)*$B$14)/B12)) -> 5.2707156 | D22: Después de cada reposición el ahorro cae; desde esta fecha ya no vuelve a ser negativo
A23: Inversión: pago único el día 1 (con IVA)
A24: Proveedor | B24: En dólares | C24: En pesos | D24: Total en pesos
A25: Romela Toldos (lona) | B25: 17873 | C25: 0 | D25: =B25*$B$5+C25 -> 714920
A26: Appelsa (postes y estructura) | B26: 4180.6228 | C26: 0 | D26: =B26*$B$5+C26 -> 167224.91
A27: Bianchi (cables y accesorios) | B27: 503.78 | C27: 127301 | D27: =B27*$B$5+C27 -> 147452.2
A28: Sodimac (anclajes) | B28: 0 | C28: 10146 | D28: =B28*$B$5+C28 -> 10146
A29: Polietileno Obelisco (cuerda) | B29: 0 | C29: 14400 | D29: =B29*$B$5+C29 -> 14400
A30: Total a pagar el día 1 | B30: =SUM(B25:B29) -> 22557.403 | C30: =SUM(C25:C29) -> 151847 | D30: =SUM(D25:D29) -> 1054143.1
A31: Fuente: Gastos.xlsx (hoja Gastos), con IVA, precios al 1/10/2026. Si cambian allá, actualizar las celdas azules.
A33: ¿Y si los eventos por año son otros?
A34: Eventos por año | B34: Años para recuperar: conservador | C34: Años para recuperar: realista | D34: Ahorro neto en el horizonte: conservador | E34: Ahorro neto en el horizonte: realista
A35: 1 | B35: =IF(($A35*$B$7)*$B$8>=$B$13,$B$13/($A35*$B$7),IF(($A35*$B$7)*$B$8<=$B$14,"nunca",($B$13+ROUNDUP(($B$13-($A35*$B$7)*$B$8)/(($A35*$B$7)*$B$8-$B$14),0)*$B$14)/($A35*$B$7))) -> nunca | C35: =IF(($A35*$B$7)*$B$9>=$B$13,$B$13/($A35*$B$7),IF(($A35*$B$7)*$B$9<=$B$14,"nunca",($B$13+ROUNDUP(($B$13-($A35*$B$7)*$B$9)/(($A35*$B$7)*$B$9-$B$14),0)*$B$14)/($A35*$B$7))) -> 17.834631 | D35: =($A35*$B$7)*$B$15-$B$13-$B$14*$B$16 -> -1242103.1 | E35: =($A35*$B$7)*$B$15-$B$13-$B$14*$C$16 -> 216536.89
A36: 2 | B36: =IF(($A36*$B$7)*$B$8>=$B$13,$B$13/($A36*$B$7),IF(($A36*$B$7)*$B$8<=$B$14,"nunca",($B$13+ROUNDUP(($B$13-($A36*$B$7)*$B$8)/(($A36*$B$7)*$B$8-$B$14),0)*$B$14)/($A36*$B$7))) -> 8.9173156 | C36: =IF(($A36*$B$7)*$B$9>=$B$13,$B$13/($A36*$B$7),IF(($A36*$B$7)*$B$9<=$B$14,"nunca",($B$13+ROUNDUP(($B$13-($A36*$B$7)*$B$9)/(($A36*$B$7)*$B$9-$B$14),0)*$B$14)/($A36*$B$7))) -> 5.2707156 | D36: =($A36*$B$7)*$B$15-$B$13-$B$14*$B$16 -> 757896.89 | E36: =($A36*$B$7)*$B$15-$B$13-$B$14*$C$16 -> 2216536.9
A37: 4 | B37: =IF(($A37*$B$7)*$B$8>=$B$13,$B$13/($A37*$B$7),IF(($A37*$B$7)*$B$8<=$B$14,"nunca",($B$13+ROUNDUP(($B$13-($A37*$B$7)*$B$8)/(($A37*$B$7)*$B$8-$B$14),0)*$B$14)/($A37*$B$7))) -> 2.6353578 | C37: =IF(($A37*$B$7)*$B$9>=$B$13,$B$13/($A37*$B$7),IF(($A37*$B$7)*$B$9<=$B$14,"nunca",($B$13+ROUNDUP(($B$13-($A37*$B$7)*$B$9)/(($A37*$B$7)*$B$9-$B$14),0)*$B$14)/($A37*$B$7))) -> 2.6353578 | D37: =($A37*$B$7)*$B$15-$B$13-$B$14*$B$16 -> 4757896.9 | E37: =($A37*$B$7)*$B$15-$B$13-$B$14*$C$16 -> 6216536.9
A38: 6 | B38: =IF(($A38*$B$7)*$B$8>=$B$13,$B$13/($A38*$B$7),IF(($A38*$B$7)*$B$8<=$B$14,"nunca",($B$13+ROUNDUP(($B$13-($A38*$B$7)*$B$8)/(($A38*$B$7)*$B$8-$B$14),0)*$B$14)/($A38*$B$7))) -> 1.7569052 | C38: =IF(($A38*$B$7)*$B$9>=$B$13,$B$13/($A38*$B$7),IF(($A38*$B$7)*$B$9<=$B$14,"nunca",($B$13+ROUNDUP(($B$13-($A38*$B$7)*$B$9)/(($A38*$B$7)*$B$9-$B$14),0)*$B$14)/($A38*$B$7))) -> 1.7569052 | D38: =($A38*$B$7)*$B$15-$B$13-$B$14*$B$16 -> 8757896.9 | E38: =($A38*$B$7)*$B$15-$B$13-$B$14*$C$16 -> 10216537
A39: 12 | B39: =IF(($A39*$B$7)*$B$8>=$B$13,$B$13/($A39*$B$7),IF(($A39*$B$7)*$B$8<=$B$14,"nunca",($B$13+ROUNDUP(($B$13-($A39*$B$7)*$B$8)/(($A39*$B$7)*$B$8-$B$14),0)*$B$14)/($A39*$B$7))) -> 0.87845259 | C39: =IF(($A39*$B$7)*$B$9>=$B$13,$B$13/($A39*$B$7),IF(($A39*$B$7)*$B$9<=$B$14,"nunca",($B$13+ROUNDUP(($B$13-($A39*$B$7)*$B$9)/(($A39*$B$7)*$B$9-$B$14),0)*$B$14)/($A39*$B$7))) -> 0.87845259 | D39: =($A39*$B$7)*$B$15-$B$13-$B$14*$B$16 -> 20757897 | E39: =($A39*$B$7)*$B$15-$B$13-$B$14*$C$16 -> 22216537
A40: Los saltos: cada vez que hay que reponer la lona el ahorro acumulado cae, por eso el tiempo para recuperar no baja de forma pareja.
A41: «nunca»: con muy pocos usos, el desgaste de la lona se come todo lo que se ahorra en carpa.
A43: Flujo año por año
...
